<?xml version="1.0" encoding="UTF-8"?>
<!-- Generated by org.testng.reporters.JUnitReportReporter -->
<testsuite hostname="BhushanPatil" failures="1" tests="4" name="ITestListener.ITestListenerWithExample" time="1.072" errors="1" timestamp="2023-10-08T22:47:09 IST" skipped="1">
  <testcase classname="ITestListener.ITestListenerWithExample" name="TestFailed" time="1.041">
    <error message="Method ITestListener.ITestListenerWithExample.TestFailed() didn&#039;t finish within the time-out 1000" type="org.testng.internal.thread.ThreadTimeoutException">
      <![CDATA[org.testng.internal.thread.ThreadTimeoutException: Method ITestListener.ITestListenerWithExample.TestFailed() didn't finish within the time-out 1000
at java.base@11.0.18/java.lang.Thread.sleep(Native Method)
at app//ITestListener.ITestListenerWithExample.TestFailed(ITestListenerWithExample.java:20)
at java.base@11.0.18/jdk.internal.reflect.NativeMethodAccessorImpl.invoke0(Native Method)
at java.base@11.0.18/jdk.internal.reflect.NativeMethodAccessorImpl.invoke(NativeMethodAccessorImpl.java:62)
at java.base@11.0.18/jdk.internal.reflect.DelegatingMethodAccessorImpl.invoke(DelegatingMethodAccessorImpl.java:43)
at java.base@11.0.18/java.lang.reflect.Method.invoke(Method.java:566)
at app//org.testng.internal.invokers.MethodInvocationHelper.invokeMethod(MethodInvocationHelper.java:139)
at app//org.testng.internal.invokers.InvokeMethodRunnable.runOne(InvokeMethodRunnable.java:47)
at app//org.testng.internal.invokers.InvokeMethodRunnable.call(InvokeMethodRunnable.java:76)
at app//org.testng.internal.invokers.InvokeMethodRunnable.call(InvokeMethodRunnable.java:11)
at java.base@11.0.18/java.util.concurrent.FutureTask.run(FutureTask.java:264)
at java.base@11.0.18/java.util.concurrent.ThreadPoolExecutor.runWorker(ThreadPoolExecutor.java:1128)
at java.base@11.0.18/java.util.concurrent.ThreadPoolExecutor$Worker.run(ThreadPoolExecutor.java:628)
at java.base@11.0.18/java.lang.Thread.run(Thread.java:834)
]]>
    </error>
  </testcase> <!-- TestFailed -->
  <testcase classname="ITestListener.ITestListenerWithExample" name="TestFailed1" time="0.028">
    <failure message="expected [true] but found [false]" type="java.lang.AssertionError">
      <![CDATA[java.lang.AssertionError: expected [true] but found [false]
at org.testng.Assert.fail(Assert.java:111)
at org.testng.Assert.failNotEquals(Assert.java:1578)
at org.testng.Assert.assertTrue(Assert.java:57)
at org.testng.Assert.assertTrue(Assert.java:67)
at ITestListener.ITestListenerWithExample.TestFailed1(ITestListenerWithExample.java:36)
at java.base/jdk.internal.reflect.NativeMethodAccessorImpl.invoke0(Native Method)
at java.base/jdk.internal.reflect.NativeMethodAccessorImpl.invoke(NativeMethodAccessorImpl.java:62)
at java.base/jdk.internal.reflect.DelegatingMethodAccessorImpl.invoke(DelegatingMethodAccessorImpl.java:43)
at java.base/java.lang.reflect.Method.invoke(Method.java:566)
at org.testng.internal.invokers.MethodInvocationHelper.invokeMethod(MethodInvocationHelper.java:139)
at org.testng.internal.invokers.TestInvoker.invokeMethod(TestInvoker.java:664)
at org.testng.internal.invokers.TestInvoker.invokeTestMethod(TestInvoker.java:227)
at org.testng.internal.invokers.MethodRunner.runInSequence(MethodRunner.java:50)
at org.testng.internal.invokers.TestInvoker$MethodInvocationAgent.invoke(TestInvoker.java:957)
at org.testng.internal.invokers.TestInvoker.invokeTestMethods(TestInvoker.java:200)
at org.testng.internal.invokers.TestMethodWorker.invokeTestMethods(TestMethodWorker.java:148)
at org.testng.internal.invokers.TestMethodWorker.run(TestMethodWorker.java:128)
at java.base/java.util.ArrayList.forEach(ArrayList.java:1541)
at org.testng.TestRunner.privateRun(TestRunner.java:848)
at org.testng.TestRunner.run(TestRunner.java:621)
at org.testng.SuiteRunner.runTest(SuiteRunner.java:443)
at org.testng.SuiteRunner.runSequentially(SuiteRunner.java:437)
at org.testng.SuiteRunner.privateRun(SuiteRunner.java:397)
at org.testng.SuiteRunner.run(SuiteRunner.java:336)
at org.testng.SuiteRunnerWorker.runSuite(SuiteRunnerWorker.java:52)
at org.testng.SuiteRunnerWorker.run(SuiteRunnerWorker.java:95)
at org.testng.TestNG.runSuitesSequentially(TestNG.java:1280)
at org.testng.TestNG.runSuitesLocally(TestNG.java:1200)
at org.testng.TestNG.runSuites(TestNG.java:1114)
at org.testng.TestNG.run(TestNG.java:1082)
at org.testng.remote.AbstractRemoteTestNG.run(AbstractRemoteTestNG.java:115)
at org.testng.remote.RemoteTestNG.initAndRun(RemoteTestNG.java:251)
at org.testng.remote.RemoteTestNG.main(RemoteTestNG.java:77)
]]>
    </failure>
  </testcase> <!-- TestFailed1 -->
  <testcase classname="ITestListener.ITestListenerWithExample" name="TestPassed" time="0.003"/>
  <testcase classname="ITestListener.ITestListenerWithExample" name="TestSkipped" time="0.000">
    <skipped/>
  </testcase> <!-- TestSkipped -->
</testsuite> <!-- ITestListener.ITestListenerWithExample -->
